Traceback (most recent call last):
  File "/Users/kristian/miniforge3/envs/IND320_2024/lib/python3.12/site-packages/jupyter_cache/executors/utils.py", line 58, in single_nb_execution
    executenb(
  File "/Users/kristian/miniforge3/envs/IND320_2024/lib/python3.12/site-packages/nbclient/client.py", line 1314, in execute
    return NotebookClient(nb=nb, resources=resources, km=km, **kwargs).execute()
           ^^^^^^^^^^^^^^^^^^^^^^^^^^^^^^^^^^^^^^^^^^^^^^^^^^^^^^^^^^^^^^^^^^^^^
  File "/Users/kristian/miniforge3/envs/IND320_2024/lib/python3.12/site-packages/jupyter_core/utils/__init__.py", line 165, in wrapped
    return loop.run_until_complete(inner)
           ^^^^^^^^^^^^^^^^^^^^^^^^^^^^^^
  File "/Users/kristian/miniforge3/envs/IND320_2024/lib/python3.12/asyncio/base_events.py", line 687, in run_until_complete
    return future.result()
           ^^^^^^^^^^^^^^^
  File "/Users/kristian/miniforge3/envs/IND320_2024/lib/python3.12/site-packages/nbclient/client.py", line 709, in async_execute
    await self.async_execute_cell(
  File "/Users/kristian/miniforge3/envs/IND320_2024/lib/python3.12/site-packages/nbclient/client.py", line 1062, in async_execute_cell
    await self._check_raise_for_error(cell, cell_index, exec_reply)
  File "/Users/kristian/miniforge3/envs/IND320_2024/lib/python3.12/site-packages/nbclient/client.py", line 918, in _check_raise_for_error
    raise CellExecutionError.from_cell_and_msg(cell, exec_reply_content)
nbclient.exceptions.CellExecutionError: An error occurred while executing the following cell:
------------------
# Insert a new row into the first_test table with the values 3, 'Pete', 'Data Science'
query = "INSERT INTO students VALUES (3, 'Pete', 'Data Science');"
# This can result in an error if the primary key already exists
cursor.execute(query)
------------------


[0;31m---------------------------------------------------------------------------[0m
[0;31mIntegrityError[0m                            Traceback (most recent call last)
Cell [0;32mIn[6], line 4[0m
[1;32m      2[0m query [38;5;241m=[39m [38;5;124m"[39m[38;5;124mINSERT INTO students VALUES (3, [39m[38;5;124m'[39m[38;5;124mPete[39m[38;5;124m'[39m[38;5;124m, [39m[38;5;124m'[39m[38;5;124mData Science[39m[38;5;124m'[39m[38;5;124m);[39m[38;5;124m"[39m
[1;32m      3[0m [38;5;66;03m# This can result in an error if the primary key already exists[39;00m
[0;32m----> 4[0m [43mcursor[49m[38;5;241;43m.[39;49m[43mexecute[49m[43m([49m[43mquery[49m[43m)[49m

File [0;32m~/miniforge3/envs/IND320_2024/lib/python3.12/site-packages/mysql/connector/cursor.py:551[0m, in [0;36mMySQLCursor.execute[0;34m(self, operation, params, multi)[0m
[1;32m    549[0m [38;5;28;01melse[39;00m:
[1;32m    550[0m     [38;5;28;01mtry[39;00m:
[0;32m--> 551[0m         [38;5;28mself[39m[38;5;241m.[39m_handle_result([38;5;28;43mself[39;49m[38;5;241;43m.[39;49m[43m_connection[49m[38;5;241;43m.[39;49m[43mcmd_query[49m[43m([49m[43mstmt[49m[43m)[49m)
[1;32m    552[0m     [38;5;28;01mexcept[39;00m errors[38;5;241m.[39mInterfaceError:
[1;32m    553[0m         [38;5;28;01mif[39;00m [38;5;28mself[39m[38;5;241m.[39m_connection[38;5;241m.[39m_have_next_result:  [38;5;66;03m# pylint: disable=W0212[39;00m

File [0;32m~/miniforge3/envs/IND320_2024/lib/python3.12/site-packages/mysql/connector/connection.py:490[0m, in [0;36mMySQLConnection.cmd_query[0;34m(self, query, raw, buffered, raw_as_string)[0m
[1;32m    488[0m [38;5;28;01mif[39;00m [38;5;129;01mnot[39;00m [38;5;28misinstance[39m(query, [38;5;28mbytes[39m):
[1;32m    489[0m     query [38;5;241m=[39m query[38;5;241m.[39mencode([38;5;124m'[39m[38;5;124mutf-8[39m[38;5;124m'[39m)
[0;32m--> 490[0m result [38;5;241m=[39m [38;5;28;43mself[39;49m[38;5;241;43m.[39;49m[43m_handle_result[49m[43m([49m[38;5;28;43mself[39;49m[38;5;241;43m.[39;49m[43m_send_cmd[49m[43m([49m[43mServerCmd[49m[38;5;241;43m.[39;49m[43mQUERY[49m[43m,[49m[43m [49m[43mquery[49m[43m)[49m[43m)[49m
[1;32m    492[0m [38;5;28;01mif[39;00m [38;5;28mself[39m[38;5;241m.[39m_have_next_result:
[1;32m    493[0m     [38;5;28;01mraise[39;00m errors[38;5;241m.[39mInterfaceError(
[1;32m    494[0m         [38;5;124m'[39m[38;5;124mUse cmd_query_iter for statements with multiple queries.[39m[38;5;124m'[39m)

File [0;32m~/miniforge3/envs/IND320_2024/lib/python3.12/site-packages/mysql/connector/connection.py:395[0m, in [0;36mMySQLConnection._handle_result[0;34m(self, packet)[0m
[1;32m    393[0m     [38;5;28;01mreturn[39;00m [38;5;28mself[39m[38;5;241m.[39m_handle_eof(packet)
[1;32m    394[0m [38;5;28;01melif[39;00m packet[[38;5;241m4[39m] [38;5;241m==[39m [38;5;241m255[39m:
[0;32m--> 395[0m     [38;5;28;01mraise[39;00m errors[38;5;241m.[39mget_exception(packet)
[1;32m    397[0m [38;5;66;03m# We have a text result set[39;00m
[1;32m    398[0m column_count [38;5;241m=[39m [38;5;28mself[39m[38;5;241m.[39m_protocol[38;5;241m.[39mparse_column_count(packet)

[0;31mIntegrityError[0m: 1062 (23000): Duplicate entry '3' for key 'PRIMARY'

